I'm sorry, but an uncaught exception occurred.

While running game code:
  File "game/level_4.rpy", line 49, in script
    $ rules = [
  File "game/level_4.rpy", line 53, in <module>
    ("Password must include a number. Try the result of 50 * (4 + 6) - 100 / 2 (hint: 45_)",lambda pwd: pwd == 'Yerffej450')
TypeError: 'tuple' object is not callable

-- Full Traceback ------------------------------------------------------------

Full traceback:
  File "game/level_4.rpy", line 49, in script
    $ rules = [
  File "C:\SeAdv\renpy\renpy-8.1.3-sdk\renpy\ast.py", line 1138, in execute
    renpy.python.py_exec_bytecode(self.code.bytecode, self.hide, store=self.store)
  File "C:\SeAdv\renpy\renpy-8.1.3-sdk\renpy\python.py", line 1122, in py_exec_bytecode
    exec(bytecode, globals, locals)
  File "game/level_4.rpy", line 53, in <module>
    ("Password must include a number. Try the result of 50 * (4 + 6) - 100 / 2 (hint: 45_)",lambda pwd: pwd == 'Yerffej450')
TypeError: 'tuple' object is not callable

Windows-10-10.0.22631 AMD64
Ren'Py 8.1.3.23091805
Social Engineering Game 1.0
Sat Jun 15 00:59:36 2024
