I'm sorry, but an uncaught exception occurred.

While running game code:
  File "game/level_3.rpy", line 890, in script
    hs "What do you think you're doing?! This is a private room!"
Exception: Sayer 'hs' is not defined.

-- Full Traceback ------------------------------------------------------------

Full traceback:
  File "game/level_3.rpy", line 890, in script
    hs "What do you think you're doing?! This is a private room!"
  File "C:\Users\49157\Downloads\renpy-8.1.3-sdk\renpy\ast.py", line 890, in execute
    who = eval_who(self.who, self.who_fast)
  File "C:\Users\49157\Downloads\renpy-8.1.3-sdk\renpy\ast.py", line 783, in eval_who
    raise Exception("Sayer '%s' is not defined." % who)
Exception: Sayer 'hs' is not defined.

Windows-10-10.0.22631 AMD64
Ren'Py 8.1.3.23091805
Social Engineering Game 1.0
Mon Apr 29 12:41:48 2024
