I'm sorry, but an uncaught exception occurred.

While running game code:
  File "game/level_3.rpy", line 428, in script
    Sec "I am afraid I can't do that sweetie. But he is fine I am sure of it! Have a nice day!"
Exception: Sayer 'Sec' is not defined.

-- Full Traceback ------------------------------------------------------------

Full traceback:
  File "game/level_3.rpy", line 428, in script
    Sec "I am afraid I can't do that sweetie. But he is fine I am sure of it! Have a nice day!"
  File "C:\Users\Deep\OneDrive\Desktop\renpy-8.1.3-sdk\renpy\ast.py", line 890, in execute
    who = eval_who(self.who, self.who_fast)
  File "C:\Users\Deep\OneDrive\Desktop\renpy-8.1.3-sdk\renpy\ast.py", line 783, in eval_who
    raise Exception("Sayer '%s' is not defined." % who)
Exception: Sayer 'Sec' is not defined.

Windows-10-10.0.22631 AMD64
Ren'Py 8.1.3.23091805
Social Engineering Game 1.0
Mon May  6 18:41:40 2024
